<?xml version="1.0"?>

<robot name="Robot1">		
	<link name="link_chassis">
    <!-- body -->
    <visual>
      <origin rpy="0 0 0" xyz="0 0 0"/>
      <geometry>
        <box size="0.5 0.3 0.07"/>
      </geometry>
    </visual>
    <!-- caster front -->
    <visual name="caster_front_visual">
      <origin rpy=" 0 0 0" xyz="0.2 0 -0.05"/>
      <geometry>
        <sphere radius="0.05"/>
      </geometry>
    </visual>
  </link>
   
   <link name="link_1">
    <visual name="link_1_visual">
      <origin rpy="0 1.5707 1.5707" xyz="0 0 0.5*z[link_1]"/>
      <geometry>
       	<cylinder length="1" radius="0.05"/>
      </geometry>
    </visual>
  </link>
   
   <link name="link_2">
    <visual name="link_2_visual">
      <origin rpy="0 1.5707 1.5707" xyz="0 0 0.5*z[link_2]"/>
      <geometry>
       	<cylinder length="1" radius="0.05"/>
      </geometry>
    </visual>
  </link>
  
   <link name="link_3">
    <visual name="link_3_visual">
      <origin rpy="0 1.5707 1.5707" xyz="0 0 0.5*z[link_3]"/>
      <geometry>
       	<cylinder length="1" radius="0.05"/>
      </geometry>
    </visual>
  </link>
   
   <link name="link_right_wheel">
    <visual name="link_right_wheel_visual">
      <origin rpy="0 1.5707 1.5707" xyz="0 0 0"/>
      <geometry>
       	<cylinder length="0.04" radius="0.1"/>
      </geometry>
    </visual>
  </link>

   <link name="link_left_wheel">
    <visual name="link_left_wheel_visual">
      <origin rpy="0 1.5707 1.5707" xyz="0 0 0"/>
      <geometry>
        <cylinder length="0.04" radius="0.1"/>
      </geometry>
    </visual>
  </link>

  <joint name="joint_1" type="continuous">
    <origin rpy="0 0 0" xyz="0 0 0.5*z[link_chassis]"/>
    <child link="link_1"/>
    <parent link="link_chassis"/>
    <axis rpy="0 0 0" xyz="0 0 1"/>
    <limit effort="10000" velocity="1000"/>
    <joint_properties damping="1.0" friction="1.0"/>
  </joint>
  
  <joint name="joint_2" type="continuous">
    <origin rpy="0 0 0" xyz="0 0 z[link_1]"/>
    <child link="link_2"/>
    <parent link="link_1"/>
    <axis rpy="0 0 0" xyz="1 0 0"/>
    <limit effort="10000" velocity="1000"/>
    <joint_properties damping="1.0" friction="1.0"/>
  </joint>

  <joint name="joint_3" type="continuous">
    <origin rpy="0 0 0" xyz="0 0 z[lonk_2]"/>
    <child link="link_3"/>
    <parent link="link_2"/>
    <axis rpy="0 0 0" xyz="1 0 0"/>
    <limit effort="10000" velocity="1000"/>
    <joint_properties damping="1.0" friction="1.0"/>
  </joint>

  <joint name="joint_right_wheel" type="continuous">
    <origin rpy="0 0 0" xyz="-0.05 0.15 0"/>
    <child link="link_right_wheel"/>
    <parent link="link_chassis"/>
    <axis rpy="0 0 0" xyz="0 1 0"/>
    <limit effort="10000" velocity="1000"/>
    <joint_properties damping="1.0" friction="1.0"/>
  </joint>
  
  
  <joint name="joint_left_wheel" type="continuous">
    <origin rpy="0 0 0" xyz="-0.05 -0.15 0"/>
    <child link="link_left_wheel"/>
    <parent link="link_chassis"/>
    <axis rpy="0 0 0" xyz="0 1 0"/>
    <limit effort="10000" velocity="1000"/>
    <joint_properties damping="1.0" friction="1.0"/>
  </joint>

</robot>
